<mujocoinclude model="MyoTorso_v0.0.1">
<!-- =================================================
	Copyright 2020 Vikash Kumar, Vittorio Caggiano, Huawei Wang
	Model	:: Myo Legs (MuJoCoV2.0)
	Author	:: Vikash Kumar (vikashplus@gmail.com), Vittorio Caggiano, Huawei Wang
	source	:: https://github.com/vikashplus
	License	:: Under Apache License, Version 2.0 (the "License"); you may not use this file except in compliance with the License. You may obtain a copy of the License at http://www.apache.org/licenses/LICENSE-2.0 Unless required by applicable law or agreed to in writing, software distributed under the License is distributed on an "AS IS" BASIS, WITHOUT WARRANTIES OR CONDITIONS OF ANY KIND, either express or implied. See the License for the specific language governing permissions and limitations under the License.
====================================================== -->

    <!-- pos="-0.1007 0 0.1" -->
    <body name="torso" pos="-0.1007 0 0.0815" euler="1.57 0 0" childclass="myotorso">
        <joint axis="0 0 1" name="lumbar_extension" pos="0 0 0" range="-1.5708 1.5708"/>
        <joint axis="1 0 0" name="lumbar_bending" pos="0 0 0" range="-.785 .785"/>
        <joint axis="0 1 0" name="lumbar_rotation" pos="0 0 0" range="-.785 .785"/>

        <body euler="-1.57 0 0" pos=".1 -.065 -.00">
            <geom type="capsule" class="myotorso_coll" size="0.080 0.077" pos="-.065 0 .070" euler="1.57 0 0"/>
            <geom type="ellipsoid" class="myotorso_coll" size="0.095 0.140 0.140" pos="-.075 0 .200" euler="1.57 0 0"/>
            <geom type="capsule" class="myotorso_coll" size="0.110 0.065" pos="-.090 0 .340" euler="1.57 0 0"/>
            <geom type="capsule" class="myotorso_coll" size="0.075 0.145" pos="-.110 0 .425" euler="1.57 0 0"/>
        </body>

        <geom mesh="hat_spine" name="hat_spine" type="mesh"/>
        <geom mesh="hat_jaw" name="hat_jaw" type="mesh"/>
        <geom mesh="hat_skull" name="hat_skull" type="mesh"/>
        <geom mesh="hat_ribs_scap" name="hat_ribs_scap" type="mesh"/>
        <site name="RACR" pos="-0.003 0.425 0.13"/>
        <site name="LACR" pos="-0.003 0.425 -0.13"/>
        <site name="C7" pos="-0.085 0.435 0.0017"/>
        <site name="CLAV" pos="0.04 0.38 0.017"/>
        <site name="RASH" pos="0.05 0.3715 0.17"/>
        <site name="RPSH" pos="-0.05 0.3715 0.17"/>
        <site name="LASH" pos="0.05 0.3715 -0.17"/>
        <site name="LPSH" pos="-0.058 0.3715 -0.17"/>
        <body name="humerus_r" pos="0.003155 0.3715 0.17">
            <joint axis="0 0 1" name="arm_flex_r" pos="0 0 0" range="-1.5708 1.5708"/>
            <joint axis="1 0 0" name="arm_add_r" pos="0 0 0" range="-2.0944 1.5708"/>
            <joint axis="0 1 0" name="arm_rot_r" pos="0 0 0" range="-1.5708 1.5708"/>
            <geom mesh="humerus_rv" name="humerus_rv" type="mesh"/>
            <geom type="capsule" class="myotorso_coll" size="0.042 0.130" pos="0 -.13 0" euler="1.57 0 0"/>
            <site name="RSJC" pos="0 0 0"/>
            <site name="RUA1" pos="0 -0.05 0.02"/>
            <site name="RUA2" pos="0 -0.2 0.02"/>
            <site name="RUA3" pos="0.03 -0.13 0.02"/>
            <site name="RLEL" pos="0.015 -0.28 0.04"/>
            <site name="RMEL" pos="0.0022 -0.286 -0.046"/>
            <body name="ulna_r" pos="0.013144 -0.286273 -0.009595">
                <joint axis="0.226047 0.022269 0.973862" name="elbow_flex_r" pos="0 0 0" range="0 2.618"/>
                <geom mesh="ulna_rv" name="ulna_rv" type="mesh"/>
                <geom type="capsule" class="myotorso_coll" size="0.030" fromto="-.01 0 0.01 -0.015 -0.235841 0.0361" euler="1.4 0.1 0.12"/>
                <site name="RFAsuperior" pos="0.0046 -0.0801 0.0453"/>
                <site name="REJC" pos="0 0 0"/>
                <body name="radius_r" pos="-0.006727 -0.013007 0.026083">
                    <joint axis="0.056398 0.998406 0.001952" name="pro_sup_r" pos="0 0 0" range="0 1.5708"/>
                    <geom mesh="radius_rv" name="radius_rv" type="mesh"/>
                    <site name="RFAradius" pos="0.0005 -0.225 0.05"/>
                    <site name="RFAulna" pos="-0.022 -0.225 -0.022"/>
                    <body name="hand_r" pos="-0.008797 -0.235841 0.01361">
                        <joint axis="0 0 1" name="wrist_flex_r" pos="0 0 0" range="-1.22173 1.22173"/>
                        <joint axis="1 0 0" name="wrist_dev_r" pos="0 0 0" range="-0.436332 0.610865"/>
                        <geom mesh="pisiform_rvs" name="pisiform_rvs" type="mesh"/>
                        <geom mesh="lunate_rvs" name="lunate_rvs" type="mesh"/>
                        <geom mesh="scaphoid_rvs" name="scaphoid_rvs" type="mesh"/>
                        <geom mesh="triquetrum_rvs" name="triquetrum_rvs" type="mesh"/>
                        <geom mesh="hamate_rvs" name="hamate_rvs" type="mesh"/>
                        <geom mesh="capitate_rvs" name="capitate_rvs" type="mesh"/>
                        <geom mesh="trapezoid_rvs" name="trapezoid_rvs" type="mesh"/>
                        <geom mesh="trapezium_rvs" name="trapezium_rvs" type="mesh"/>
                        <geom mesh="metacarpal2_rvs" name="metacarpal2_rvs" type="mesh"/>
                        <geom mesh="index_proximal_rvs" name="index_proximal_rvs" type="mesh"/>
                        <geom mesh="index_medial_rvs" name="index_medial_rvs" type="mesh"/>
                        <geom mesh="index_distal_rvs" name="index_distal_rvs" type="mesh"/>
                        <geom mesh="metacarpal3_rvs" name="metacarpal3_rvs" type="mesh"/>
                        <geom mesh="middle_proximal_rvs" name="middle_proximal_rvs" type="mesh"/>
                        <geom mesh="middle_medial_rvs" name="middle_medial_rvs" type="mesh"/>
                        <geom mesh="middle_distal_rvs" name="middle_distal_rvs" type="mesh"/>
                        <geom mesh="metacarpal4_rvs" name="metacarpal4_rvs" type="mesh"/>
                        <geom mesh="ring_proximal_rvs" name="ring_proximal_rvs" type="mesh"/>
                        <geom mesh="ring_medial_rvs" name="ring_medial_rvs" type="mesh"/>
                        <geom mesh="ring_distal_rvs" name="ring_distal_rvs" type="mesh"/>
                        <geom mesh="metacarpal5_rvs" name="metacarpal5_rvs" type="mesh"/>
                        <geom mesh="little_proximal_rvs" name="little_proximal_rvs" type="mesh"/>
                        <geom mesh="little_medial_rvs" name="little_medial_rvs" type="mesh"/>
                        <geom mesh="little_distal_rvs" name="little_distal_rvs" type="mesh"/>
                        <geom mesh="metacarpal1_rvs" name="metacarpal1_rvs" type="mesh"/>
                        <geom mesh="thumb_proximal_rvs" name="thumb_proximal_rvs" type="mesh"/>
                        <geom mesh="thumb_distal_rvs" name="thumb_distal_rvs" type="mesh"/>
                    </body>
                </body>
            </body>
        </body>
        <body name="humerus_l" pos="0.003155 0.3715 -0.17">
            <joint axis="0 0 1" name="arm_flex_l" pos="0 0 0" range="-1.5708 1.5708"/>
            <joint axis="-1 0 0" name="arm_add_l" pos="0 0 0" range="-2.0944 1.5708"/>
            <joint axis="0 -1 0" name="arm_rot_l" pos="0 0 0" range="-1.5708 1.5708"/>
            <geom mesh="humerus_lv" name="humerus_lv" type="mesh"/>
            <geom type="capsule" class="myotorso_coll" size="0.042 0.130" pos="0 -.13 0" euler="1.57 0 0"/>
            <site name="LSJC" pos="0 0 0"/>
            <site name="LUA1" pos="0 -0.05 -0.02"/>
            <site name="LUA2" pos="0 -0.2 -0.02"/>
            <site name="LUA3" pos="0.03 -0.13 -0.02"/>
            <site name="LLEL" pos="0.015 -0.28 -0.04"/>
            <site name="LMEL" pos="0.0023 -0.286 0.046"/>
            <body name="ulna_l" pos="0.013144 -0.286273 0.009595">
                <joint axis="-0.226047 -0.022269 0.973862" name="elbow_flex_l" pos="0 0 0" range="0 2.618"/>
                <geom mesh="ulna_lv" name="ulna_lv" type="mesh"/>
                <geom type="capsule" class="myotorso_coll" size="0.030" fromto="-.01 0 -.01 -0.015 -0.235841 -.0361" euler="1.4 0.1 0.12"/>
                <site name="LFAsuperior" pos="0.0046 -0.0801 -0.0453"/>
                <site name="LEJC" pos="0 0 0"/>
                <body name="radius_l" pos="-0.006727 -0.013007 -0.026083">
                    <joint axis="-0.056398 -0.998406 0.001952" name="pro_sup_l" pos="0 0 0" range="0 1.5708"/>
                    <geom mesh="radius_lv" name="radius_lv" type="mesh"/>
                    <site name="LFAradius" pos="0.0005 -0.225 -0.05"/>
                    <site name="LFAulna" pos="-0.022 -0.225 0.022"/>
                    <body name="hand_l" pos="-0.008797 -0.235841 -0.01361">
                        <joint axis="0 0 1" name="wrist_flex_l" pos="0 0 0" range="-1.22173 1.22173"/>
                        <joint axis="-1 0 0" name="wrist_dev_l" pos="0 0 0" range="-0.436332 0.610865"/>
                        <geom mesh="pisiform_lvs" name="pisiform_lvs" type="mesh"/>
                        <geom mesh="lunate_lvs" name="lunate_lvs" type="mesh"/>
                        <geom mesh="scaphoid_lvs" name="scaphoid_lvs" type="mesh"/>
                        <geom mesh="triquetrum_lvs" name="triquetrum_lvs" type="mesh"/>
                        <geom mesh="hamate_lvs" name="hamate_lvs" type="mesh"/>
                        <geom mesh="capitate_lvs" name="capitate_lvs" type="mesh"/>
                        <geom mesh="trapezoid_lvs" name="trapezoid_lvs" type="mesh"/>
                        <geom mesh="trapezium_lvs" name="trapezium_lvs" type="mesh"/>
                        <geom mesh="metacarpal2_lvs" name="metacarpal2_lvs" type="mesh"/>
                        <geom mesh="index_proximal_lvs" name="index_proximal_lvs" type="mesh"/>
                        <geom mesh="index_medial_lvs" name="index_medial_lvs" type="mesh"/>
                        <geom mesh="index_distal_lvs" name="index_distal_lvs" type="mesh"/>
                        <geom mesh="metacarpal3_lvs" name="metacarpal3_lvs" type="mesh"/>
                        <geom mesh="middle_proximal_lvs" name="middle_proximal_lvs" type="mesh"/>
                        <geom mesh="middle_medial_lvs" name="middle_medial_lvs" type="mesh"/>
                        <geom mesh="middle_distal_lvs" name="middle_distal_lvs" type="mesh"/>
                        <geom mesh="metacarpal4_lvs" name="metacarpal4_lvs" type="mesh"/>
                        <geom mesh="ring_proximal_lvs" name="ring_proximal_lvs" type="mesh"/>
                        <geom mesh="ring_medial_lvs" name="ring_medial_lvs" type="mesh"/>
                        <geom mesh="ring_distal_lvs" name="ring_distal_lvs" type="mesh"/>
                        <geom mesh="metacarpal5_lvs" name="metacarpal5_lvs" type="mesh"/>
                        <geom mesh="little_proximal_lvs" name="little_proximal_lvs" type="mesh"/>
                        <geom mesh="little_medial_lvs" name="little_medial_lvs" type="mesh"/>
                        <geom mesh="little_distal_lvs" name="little_distal_lvs" type="mesh"/>
                        <geom mesh="metacarpal1_lvs" name="metacarpal1_lvs" type="mesh"/>
                        <geom mesh="thumb_proximal_lvs" name="thumb_proximal_lvs" type="mesh"/>
                        <geom mesh="thumb_distal_lvs" name="thumb_distal_lvs" type="mesh"/>
                    </body>
                </body>
            </body>
        </body>
    <!-- </body> -->
    </body>
</mujocoinclude>
